Workbook

Sheet CO-Attainment flow
E4: IA | G4: QUIZ | I4: ASSIGNMENT
F7: CIE | I7: SEE | K7: CES
G8: 0.6 | I8: 0.4
F10: DIRECT CO-ATTAINMENT | J10: IN-DIRECT CO-ATTAINMENT
H12: 0.9 | J12: 0.1
H14: FINAL CO-ATTAINMENT

Sheet CO-PO Mapping
C1: PYTHON PROGRAMMING | D1: 2021-22 Batch
C2: Year | D2: 2024
C3: Sem | D3: VI
B4: COs | C4: CO-PO MAPPING | D4: Target set in % | E4: PO1 | F4: PO2 | G4: PO3 | H4: PO4 | I4: PO5 | J4: PO6 | K4: PO7 | L4: PO8 | M4: PO9 | N4: PO10 | O4: PO11 | P4: PSO1 | Q4: PSO2 | R4: PSO3 | S4: Average
B5: CO1 | C5: Apply the fundamental Python syntax and semantics to solve simple computational problems and interpret the concepts programming in Python. | D5: 0.8 | E5: 3 | S5: =SUM(E5:R5)/5 -> 0.6
B6: CO2 | C6: Analyze the given Python program and debug for syntax and logical errors. | D6: 0.8 | F6: 3 | H6: 2 | S6: =SUM(E6:R6)/5 -> 1
B7: CO3 | C7: Develop programs to solve variety of problem statements by implementing appropriate logic and programming techniques. | D7: 0.8 | G7: 3 | H7: 2 | S7: =SUM(E7:R7)/5 -> 1
B8: CO4 | C8: Adapt good software engineering practices and demonstrate programming skills to develop an application. | D8: 0.8 | H8: 2 | I8: 2 | M8: 1 | N8: 1 | Q8: 1 | R8: 1 | S8: =SUM(E8:R8)/5 -> 1.6

Sheet CIE+SEE
A1: SEM | B1: VI | C1: EVEN Sem
A2: SUB | B2: PYTHON PROGRAMMING
A3: Batch | B3: 2021-22 Batch
A4: Year | B4: 2024 | D4: INTERNAL ASSESMENT-1 | U4: INTERNAL ASSESSMENT - 2 | AH4: INTERNAL ASSESSMENT - 3
B5: Question no. | C5: Q1 | E5: Q2 | G5: Q3 | I5: Q4 | K5: Q5 | M5: Q6 | O5: Q7 | Q5: Q8 | S5: TOT | T5: Q1 | V5: Q2 | X5: Q3 | Z5: Q4 | AB5: Q5 | AC5: Q6 | AD5: Q7 | AE5: Q8 | AF5: TOT | AG5: Q1 | AI5: Q2 | AK5: Q3 | AM5: Q4 | AO5: Q5 | AQ5: Q6 | AS5: Q7 | AU5: Q8 | AV5: TOT | AW5: TEST | AX5: AAT (ASSGN) | AY5: FINAL | AZ5: SEE
B6: CO's | C6: 1 | D6: 2 | E6: 1 | F6: 2 | G6: 2 | H6: 3 | I6: 2 | J6: 3 | K6: 2 | L6: 3 | M6: 2 | N6: 3 | O6: 1 | P6: 3 | Q6: 1 | R6: 3 | T6: 1 | U6: 2 | V6: 1 | W6: 2 | X6: 2 | Y6: 3 | Z6: 2 | AA6: 3 | AB6: 2,3 | AC6: 2,3 | AD6: 1,3 | AE6: 1,3 | AG6: 2 | AH6: 3 | AI6: 3 | AJ6: 3 | AK6: 3 | AL6: 3 | AM6: 3 | AN6: 3 | AO6: 2 | AP6: 2 | AQ6: 3 | AR6: 3 | AS6: 2 | AT6: 2 | AU6: 4 | AX6: CO 1 2 3 4 | AZ6: 1 2 3 4
B7: Maximum Marks | C7: 6 | D7: 4 | E7: 5 | F7: 5 | G7: 6 | H7: 4 | I7: 4 | J7: 6 | K7: 5 | L7: 5 | M7: 5 | N7: 5 | O7: 4 | P7: 6 | Q7: 4 | R7: 6 | S7: =SUM(C7:R7) -> 80 | T7: 5 | U7: 5 | V7: 5 | W7: 5 | X7: 5 | Y7: 5 | Z7: 5 | AA7: 5 | AB7: 10 | AC7: 10 | AD7: 10 | AE7: 10 | AF7: =SUM(T7:AE7) -> 80 | AG7: 4 | AH7: 6 | AI7: 5 | AJ7: 5 | AK7: 6 | AL7: 4 | AM7: 5 | AN7: 5 | AO7: 5 | AP7: 5 | AQ7: 5 | AR7: 5 | AS7: 5 | AT7: 5 | AU7: 10 | AV7: =SUM(AG7:AU7) -> 80 | AW7: 30 | AX7: 20 | AY7: 50 | AZ7: 100
B8: CIE Target >=60%of the max marks | C8: =0.6*C7 -> 3.6 | D8: =0.6*D7 -> 2.4 | E8: =0.6*E7 -> 3 | F8: =0.6*F7 -> 3 | G8: =0.6*G7 -> 3.6 | H8: =0.6*H7 -> 2.4 | I8: =0.6*I7 -> 2.4 | J8: =0.6*J7 -> 3.6 | ... AZ8: =0.6*AZ7 -> 60
A9: Sl.No | B9: USN
A10: 1 | B10: 1DS21ET001 | C10: 3 | D10: 4 | F10: 5 | G10: 5 | H10: 4 | K10: 4 | L10: 4 | Q10: 4 | S10: =SUM(C10:R10) -> 33 | AF10: =SUM(T10:AE10) -> 0 | AG10: 4 | AH10: 5 | AI10: 5 | AJ10: 4 | AK10: 4 | AL10: 4 | AQ10: 1 | AR10: 1 | AS10: 2 | AT10: 2 | AV10: =SUM(AG10:AU10) -> 32 | AW10: 13 | AX10: 15 | AY10: 35 | AZ10: 57
A11: 2 | B11: 1DS21ET002 | C11: 4 | D11: 4 | E11: 5 | F11: 5 | G11: 4 | H11: 4 | K11: 4 | L11: 4 | O11: 2 | P11: 6 | S11: =SUM(C11:R11) -> 42 | T11: 6 | U11: 2 | W11: 2 | X11: 4 | Y11: 2 | AC11: 9 | AE11: 1 | AF11: =SUM(T11:AE11) -> 26 | AG11: 3 | AH11: 2 | AI11: 1 | AJ11: 1 | AK11: 2 | AL11: 1 | AV11: =SUM(AG11:AU11) -> 10 | AW11: 16 | AX11: 15 | AY11: 37 | AZ11: 55
A12: 3 | B12: 1DS21ET003 | C12: 5 | D12: 4 | E12: 3 | F12: 5 | G12: 6 | H12: 4 | K12: 4 | L12: 4 | O12: 3 | P12: 5 | S12: =SUM(C12:R12) -> 43 | T12: 5 | U12: 2 | V12: 5 | W12: 1 | X12: 2 | Y12: 2 | AB12: 4 | AE12: 6 | AF12: =SUM(T12:AE12) -> 27 | AG12: 4 | AH12: 3 | AI12: 3 | AJ12: 2 | AK12: 3 | AL12: 4 | AO12: 2 | AP12: 3 | AS12: 2 | AT12: 2 | AV12: =SUM(AG12:AU12) -> 28 | AW12: 20 | AX12: 14 | AY12: 39 | AZ12: 70
A13: 4 | B13: 1DS21ET004 | C13: 6 | D13: 4 | E13: 2 | F13: 5 | G13: 5 | H13: 3 | K13: 4 | L13: 5 | O13: 2 | P13: 5 | S13: =SUM(C13:R13) -> 41 | T13: 6 | U13: 1 | Y13: 2 | AE13: 10 | AF13: =SUM(T13:AE13) -> 19 | AG13: 3 | AH13: 1 | AI13: 3 | AJ13: 4 | AM13: 4 | AN13: 2 | AO13: 4 | AP13: 4 | AV13: =SUM(AG13:AU13) -> 25 | AW13: 17 | AX13: 16 | AY13: 33 | AZ13: 58
A14: 5 | B14: 1DS21ET005 | C14: 5 | D14: 4 | E14: 3 | F14: 5 | I14: 4 | J14: 6 | K14: 5 | L14: 4 | O14: 2 | P14: 1 | S14: =SUM(C14:R14) -> 39 | T14: 5 | U14: 1 | V14: 1 | W14: 2 | X14: 2 | Y14: 2 | AB14: 5 | AD14: 1 | AF14: =SUM(T14:AE14) -> 19 | AH14: 5 | AI14: 3 | AJ14: 1 | AK14: 2 | AL14: 2 | AM14: 1 | AS14: 2 | AT14: 1 | AV14: =SUM(AG14:AU14) -> 17 | AW14: 15 | AX14: 15 | AY14: 26 | AZ14: 56
A15: 6 | B15: 1DS21ET006 | C15: 6 | D15: 4 | E15: 3 | F15: 5 | I15: 4 | J15: 5 | K15: 5 | L15: 5 | Q15: 4 | R15: 6 | S15: =SUM(C15:R15) -> 47 | T15: 6 | U15: 1 | Z15: 1 | AA15: 2 | AC15: 8 | AD15: 9 | AF15: =SUM(T15:AE15) -> 27 | AG15: 4 | AH15: 4 | AI15: 3 | AJ15: 4 | AK15: 2 | AL15: 4 | AO15: 4 | AP15: 4 | AU15: 4 | AV15: =SUM(AG15:AU15) -> 33 | AW15: 22 | AX15: 13 | AY15: 29 | AZ15: 68
A16: 7 | B16: 1DS21ET007 | C16: 5 | D16: 4 | F16: 3 | G16: 5 | H16: 4 | L16: 2 | O16: 2 | P16: 2 | S16: =SUM(C16:R16) -> 27 | T16: 2 | Y16: 1 | AC16: 3 | AF16: =SUM(T16:AE16) -> 6 | AG16: 2 | AI16: 3 | AJ16: 1 | AP16: 2 | AV16: =SUM(AG16:AU16) -> 8 | AW16: 9 | AX16: 14 | AY16: 26 | AZ16: 46
A17: 8 | B17: 1DS21ET008 | C17: 4 | D17: 4 | E17: 1 | F17: 5 | G17: 6 | H17: 4 | K17: 4 | L17: 5 | O17: 3 | P17: 2 | S17: =SUM(C17:R17) -> 38 | T17: 5 | Y17: 1 | AC17: 6 | AF17: =SUM(T17:AE17) -> 12 | AG17: 2 | AH17: 3 | AI17: 5 | AJ17: 3 | AK17: 2 | AL17: 4 | AO17: 1 | AP17: 4 | AV17: =SUM(AG17:AU17) -> 24 | AW17: 15 | AX17: 16 | AY17: 30 | AZ17: 61
A18: 9 | B18: 1DS21ET009 | C18: 5 | D18: 4 | F18: 5 | G18: 4 | H18: 4 | K18: 4 | R18: 5 | S18: =SUM(C18:R18) -> 31 | T18: 4 | U18: 1 | W18: 2 | Y18: 4 | AC18: 8 | AD18: 4 | AF18: =SUM(T18:AE18) -> 23 | AG18: 2 | AH18: 1 | AJ18: 3 | AK18: 3 | AU18: 2 | AV18: =SUM(AG18:AU18) -> 11 | AW18: 13 | AX18: 16 | AY18: 35 | AZ18: 60
A19: 10 | B19: 1DS21ET011 | C19: 4 | D19: 4 | E19: 1 | F19: 5 | G19: 3 | H19: 6 | K19: 5 | L19: 5 | O19: 4 | P19: 6 | S19: =SUM(C19:R19) -> 43 | T19: 5 | Z19: 2 | AA19: 2 | AC19: 2 | AD19: 2 | AF19: =SUM(T19:AE19) -> 13 | AG19: 3 | AH19: 5 | AI19: 3 | AJ19: 4 | AK19: 4 | AL19: 1 | AQ19: 2 | AR19: 2 | AU19: 8 | AV19: =SUM(AG19:AU19) -> 32 | AW19: 18 | AX19: 12 | AY19: 38 | AZ19: 60
A20: 11 | B20: 1DS21ET012 | C20: 4 | D20: 4 | F20: 4 | G20: 6 | H20: 4 | L20: 5 | O20: 2 | P20: 5 | S20: =SUM(C20:R20) -> 34 | T20: 5 | U20: 2 | V20: 4 | X20: 4 | Y20: 2 | AD20: 8 | AF20: =SUM(T20:AE20) -> 25 | AG20: 4 | AH20: 5 | AI20: 3 | AK20: 3 | AL20: 2 | AO20: 3 | AP20: 3 | AS20: 2 | AT20: 2 | AV20: =SUM(AG20:AU20) -> 27 | AW20: 18 | AX20: 15 | AY20: 37 | AZ20: 60
A21: 12 | B21: 1DS21ET013 | C21: 5 | D21: 4 | E21: 1 | F21: 5 | G21: 6 | H21: 4 | K21: 5 | L21: 5 | O21: 2 | P21: 5 | S21: =SUM(C21:R21) -> 42 | T21: 6 | U21: 1 | V21: 2 | Z21: 2 | AC21: 5 | AE21: 1 | AF21: =SUM(T21:AE21) -> 17 | AG21: 3 | AH21: 3 | AI21: 3 | AJ21: 3 | AK21: 2 | AL21: 2 | AV21: =SUM(AG21:AU21) -> 16 | AW21: 16 | AX21: 15 | AY21: 28 | AZ21: 64
A22: 13 | B22: 1DS21ET015 | C22: 4 | D22: 4 | F22: 5 | H22: 4 | K22: 4 | L22: 1 | O22: 4 | P22: 2 | S22: =SUM(C22:R22) -> 28 | T22: 6 | U22: 2 | W22: 3 | Y22: 2 | AC22: 6 | AF22: =SUM(T22:AE22) -> 19 | AG22: 2 | AH22: 5 | AI22: 3 | AJ22: 4 | AK22: 3 | AL22: 2 | AV22: =SUM(AG22:AU22) -> 19 | AW22: 15 | AX22: 14 | AY22: 33 | AZ22: 50
A23: 14 | B23: 1DS21ET016 | C23: 5 | D23: 4 | E23: 1 | F23: 5 | G23: 6 | H23: 4 | K23: 5 | L23: 5 | O23: 4 | P23: 6 | S23: =SUM(C23:R23) -> 45 | T23: 6 | U23: 3 | V23: 6 | W23: 2 | X23: 4 | Y23: 5 | AC23: 9 | AE23: 9 | AF23: =SUM(T23:AE23) -> 44 | AG23: 4 | AH23: 5 | AI23: 5 | AJ23: 4 | AN23: 4 | AO23: 2 | AP23: 2 | AU23: 8 | AV23: =SUM(AG23:AU23) -> 34 | AW23: 25 | AX23: 11 | AY23: 40 | AZ23: 72
A24: 15 | B24: 1DS21ET017 | C24: 4 | D24: 4 | E24: 5 | F24: 5 | G24: 6 | H24: 4 | K24: 4 | L24: 5 | Q24: 1 | R24: 4 | S24: =SUM(C24:R24) -> 42 | T24: 6 | U24: 1 | W24: 2 | X24: 3 | AC24: 7 | AE24: 1 | AF24: =SUM(T24:AE24) -> 20 | AG24: 2 | AH24: 2 | AI24: 3 | AJ24: 3 | AK24: 2 | AL24: 2 | AU24: 5 | AV24: =SUM(AG24:AU24) -> 19 | AW24: 17 | AX24: 14 | AY24: 42 | AZ24: 59
A25: 16 | B25: 1DS21ET018 | C25: 2 | D25: 4 | E25: 1 | F25: 5 | G25: 6 | H25: 4 | K25: 4 | L25: 1 | O25: 4 | P25: 6 | S25: =SUM(C25:R25) -> 37 | T25: 6 | U25: 2 | W25: 2 | X25: 4 | Y25: 2 | AC25: 9 | AF25: =SUM(T25:AE25) -> 25 | AG25: 3 | AH25: 3 | AI25: 2 | AK25: 1 | AL25: 2 | AS25: 1 | AT25: 1 | AV25: =SUM(AG25:AU25) -> 13 | AW25: 15 | AX25: 16 | AY25: 38 | AZ25: 52
A26: 17 | B26: 1DS21ET019 | C26: 5 | D26: 4 | E26: 3 | F26: 5 | G26: 6 | H26: 4 | K26: 5 | L26: 5 | O26: 2 | P26: 6 | S26: =SUM(C26:R26) -> 45 | T26: 5 | U26: 2 | V26: 2 | X26: 2 | Y26: 1 | AC26: 4 | AE26: 1 | AF26: =SUM(T26:AE26) -> 17 | AG26: 2 | AH26: 4 | AI26: 3 | AJ26: 3 | AK26: 4 | AL26: 3 | AO26: 4 | AP26: 3 | AU26: 2 | AV26: =SUM(AG26:AU26) -> 28 | AW26: 18 | AX26: 14 | AY26: 35 | AZ26: 59
A27: 18 | B27: 1DS21ET020 | C27: 5 | D27: 4 | E27: 3 | F27: 5 | I27: 4 | J27: 6 | K27: 4 | L27: 5 | O27: 4 | P27: 6 | S27: =SUM(C27:R27) -> 46 | T27: 6 | U27: 3 | V27: 5 | W27: 1 | X27: 4 | Y27: 2 | AC27: 6 | AE27: 9 | AF27: =SUM(T27:AE27) -> 36 | AG27: 4 | AH27: 3 | AI27: 5 | AJ27: 4 | AK27: 2 | AL27: 3 | AO27: 1 | AP27: 4 | AS27: 2 | AT27: 2 | AV27: =SUM(AG27:AU27) -> 30 | AW27: 23 | AX27: 14 | AY27: 40 | AZ27: 65
A28: 19 | B28: 1DS21ET021 | C28: 5 | D28: 4 | F28: 5 | G28: 6 | H28: 4 | M28: 4 | N28: 4 | O28: 4 | P28: 6 | S28: =SUM(C28:R28) -> 42 | T28: 6 | U28: 2 | V28: 1 | W28: 3 | X28: 4 | Y28: 5 | AC28: 8 | AD28: 6 | AF28: =SUM(T28:AE28) -> 35 | AG28: 2 | AH28: 2 | AI28: 3 | AJ28: 4 | AK28: 4 | AL28: 3 | AP28: 4 | AS28: 2 | AT28: 1 | AV28: =SUM(AG28:AU28) -> 25 | AW28: 21 | AX28: 20 | AY28: 40 | AZ28: 75
A29: 20 | B29: 1DS21ET022 | C29: 5 | D29: 4 | F29: 5 | G29: 6 | H29: 4 | K29: 2 | O29: 4 | P29: 2 | S29: =SUM(C29:R29) -> 32 | T29: 1 | Y29: 4 | AA29: 2 | AB29: 8 | AD29: 5 | AF29: =SUM(T29:AE29) -> 20 | AG29: 4 | AH29: 4 | AI29: 5 | AJ29: 4 | AN29: 1 | AO29: 4 | AU29: 8 | AV29: =SUM(AG29:AU29) -> 30 | AW29: 16 | AX29: 13 | AY29: 35 | AZ29: 53
A30: 21 | B30: 1DS21ET023 | C30: 3 | D30: 4 | E30: 1 | F30: 5 | G30: 6 | H30: 4 | K30: 4 | L30: 4 | R30: 5 | S30: =SUM(C30:R30) -> 36 | T30: 6 | V30: 2 | W30: 2 | X30: 1 | Y30: 2 | AC30: 4 | AE30: 2 | AF30: =SUM(T30:AE30) -> 19 | AG30: 1 | AH30: 1 | AJ30: 1 | AV30: =SUM(AG30:AU30) -> 3 | AW30: 12 | AX30: 14 | AY30: 37 | AZ30: 40
A31: 22 | B31: 1DS21ET024 | C31: 5 | D31: 4 | F31: 5 | I31: 3 | J31: 6 | K31: 1 | L31: 2 | Q31: 1 | S31: =SUM(C31:R31) -> 27 | T31: 2 | AB31: 1 | AD31: 2 | AF31: =SUM(T31:AE31) -> 5 | AI31: 3 | AO31: 1 | AU31: 5 | AV31: =SUM(AG31:AU31) -> 9 | AW31: 9 | AX31: 19 | AY31: 31 | AZ31: 41
A32: 23 | B32: 1DS21ET025 | C32: 6 | D32: 4 | E32: 2 | F32: 5 | I32: 4 | J32: 6 | K32: 2 | L32: 5 | O32: 3 | P32: 6 | S32: =SUM(C32:R32) -> 43 | T32: 5 | U32: 1 | Z32: 1 | AC32: 4 | AD32: 2 | AF32: =SUM(T32:AE32) -> 13 | AG32: 4 | AH32: 2 | AI32: 3 | AJ32: 4 | AK32: 4 | AL32: 3 | AQ32: 4 | AU32: 5 | AV32: =SUM(AG32:AU32) -> 29 | AW32: 17 | AX32: 13 | AY32: 31 | AZ32: 54
A33: 24 | B33: 1DS21ET028 | C33: 3 | D33: 4 | E33: 1 | F33: 5 | G33: 6 | H33: 4 | K33: 5 | L33: 5 | P33: 6 | S33: =SUM(C33:R33) -> 39 | T33: 5 | Z33: 2 | AC33: 4 | AE33: 1 | AF33: =SUM(T33:AE33) -> 12 | AG33: 4 | AH33: 4 | AI33: 1 | AJ33: 4 | AK33: 2 | AL33: 4 | AV33: =SUM(AG33:AU33) -> 19 | AW33: 14 | AX33: 15 | AY33: 33 | AZ33: 42
A34: 25 | B34: 1DS21ET029 | C34: 4 | D34: 4 | F34: 5 | I34: 4 | J34: 4 | K34: 4 | L34: 1 | O34: 2 | P34: 2 | S34: =SUM(C34:R34) -> 30 | T34: 4 | U34: 1 | V34: 2 | W34: 1 | X34: 4 | Y34: 2 | AC34: 6 | AE34: 5 | AF34: =SUM(T34:AE34) -> 25 | AG34: 3 | AH34: 5 | AI34: 4 | AJ34: 3 | AK34: 4 | AL34: 3 | AS34: 4 | AT34: 1 | AV34: =SUM(AG34:AU34) -> 27 | AW34: 17 | AX34: 15 | AY34: 40 | AZ34: 58
A35: 26 | B35: 1DS21ET030 | C35: 6 | D35: 4 | E35: 1 | F35: 5 | G35: 4 | H35: 4 | K35: 4 | L35: 5 | Q35: 3 | R35: 6 | S35: =SUM(C35:R35) -> 42 | T35: 5 | V35: 3 | W35: 2 | X35: 4 | Y35: 2 | AC35: 9 | AE35: 10 | AF35: =SUM(T35:AE35) -> 35 | AG35: 2 | AH35: 3 | AI35: 3 | AJ35: 2 | AK35: 1 | AL35: 2 | AN35: 1 | AU35: 2 | AV35: =SUM(AG35:AU35) -> 16 | AW35: 19 | AX35: 15 | AY35: 38 | AZ35: 51
A36: 27 | B36: 1DS21ET031 | C36: 6 | D36: 4 | E36: 1 | F36: 5 | G36: 6 | H36: 4 | K36: 5 | L36: 5 | O36: 4 | P36: 6 | S36: =SUM(C36:R36) -> 46 | T36: 6 | U36: 4 | V36: 6 | W36: 2 | X36: 4 | Y36: 2 | AC36: 10 | AE36: 10 | AF36: =SUM(T36:AE36) -> 44 | AG36: 3 | AH36: 6 | AI36: 3 | AK36: 5 | AL36: 3 | AP36: 2 | AU36: 8 | AV36: =SUM(AG36:AU36) -> 30 | AW36: 24 | AX36: 19 | AY36: 34 | AZ36: 71
A37: 28 | B37: 1DS21ET032 | S37: =SUM(C37:R37) -> 0 | AF37: =SUM(T37:AE37) -> 0 | AI37: 3 | AN37: 2 | AR37: 1 | AV37: =SUM(AG37:AU37) -> 6 | AW37: 2 | AX37: 14 | AY37: 22 | AZ37: 0
A38: 29 | B38: 1DS21ET033 | C38: 5 | D38: 4 | E38: 1 | F38: 5 | G38: 6 | H38: 4 | K38: 4 | L38: 5 | Q38: 3 | R38: 3 | S38: =SUM(C38:R38) -> 40 | T38: 6 | U38: 1 | V38: 1 | X38: 6 | Y38: 2 | AC38: 8 | AE38: 2 | AF38: =SUM(T38:AE38) -> 26 | AG38: 3 | AH38: 5 | AI38: 3 | AJ38: 4 | AK38: 2 | AL38: 4 | AS38: 2 | AT38: 1 | AV38: =SUM(AG38:AU38) -> 24 | AW38: 18 | AX38: 16 | AY38: 37 | AZ38: 48
A39: 30 | B39: 1DS21ET034 | C39: 5 | D39: 4 | F39: 5 | G39: 6 | H39: 4 | K39: 5 | L39: 4 | O39: 4 | P39: 6 | S39: =SUM(C39:R39) -> 43 | T39: 6 | U39: 4 | V39: 6 | W39: 2 | X39: 5 | Y39: 4 | AB39: 10 | AD39: 6 | AF39: =SUM(T39:AE39) -> 43 | AI39: 1 | AM39: 4 | AN39: 1 | AO39: 1 | AS39: 5 | AT39: 4 | AV39: =SUM(AG39:AU39) -> 16 | AW39: 21 | AX39: 19 | AY39: 37 | AZ39: 73
A40: 31 | B40: 1DS21ET035 | C40: 5 | D40: 4 | F40: 5 | I40: 3 | J40: 6 | K40: 4 | L40: 2 | O40: 2 | P40: 5 | S40: =SUM(C40:R40) -> 36 | U40: 2 | V40: 4 | AA40: 4 | AC40: 8 | AF40: =SUM(T40:AE40) -> 18 | AG40: 5 | AH40: 4 | AI40: 2 | AO40: 4 | AS40: 5 | AT40: 4 | AV40: =SUM(AG40:AU40) -> 24 | AW40: 16 | AX40: 17 | AY40: 29 | AZ40: 54
...

Sheet CES
C1: COURSE END SURVEY (CES)
B3: Course Outcomes : After completion of the course, the graduates will be able to | E3: SCALE | F3: RESPONSES | G3: % | H3: WEIGHTAGE | I3: FINAL
B4: CO1 | C4: Apply the fundamental Python syntax and semantics to solve simple computational problems and interpret the concepts programming in Python. | E4: STRONGLY AGREE | F4: 41 | G4: 58 | I4: =((F4*3)+(F5*2)+(F6*1))/(71*3) -> 0.84976526
B5: CO2 | C5: Analyze the given Python program and debug for syntax and logical errors. | E5: AGREE | F5: 28 | G5: 39
B6: CO3 | C6: Develop programs to solve variety of problem statements by implementing appropriate logic and programming techniques. | E6: DISAGREE | F6: 2 | G6: 3
B7: CO4 | C7: Adapt good software engineering practices and demonstrate programming skills to develop an application. | E7: TOTAL
I9: 85
C12: Process used for Indirect Assessment ( Course End Survey)

Sheet CO-Attainment
B2: CIE CO-Attainment | J2: SEE CO-Attainment
B3: COs | C3: CO1 | D3: CO2 | E3: CO3 | F3: CO4 | J3: Cos | K3: CO1 | L3: CO2 | M3: CO3 | N3: CO4
B4: IA(1+2+3) | C4: ='CIE+SEE'!AX113 -> 68.554383 | D4: ='CIE+SEE'!AX110 -> 65.478052 | E4: ='CIE+SEE'!AX111 -> 65.619159 | F4: ='CIE+SEE'!AX112 -> 76.315789 | J4: SEE CO-Attainment | K4: ='CIE+SEE'!$AZ$106 -> 36.144578 | L4: ='CIE+SEE'!$AZ$106 -> 36.144578 | M4: ='CIE+SEE'!$AZ$106 -> 36.144578 | N4: ='CIE+SEE'!$AZ$106 -> 36.144578
B5: ASSIGNMENT | C5: ='CIE+SEE'!AX106 -> 97.849462 | D5: ='CIE+SEE'!AX106 -> 97.849462 | E5: ='CIE+SEE'!AX106 -> 97.849462 | F5: ='CIE+SEE'!AX106 -> 97.849462
B6: CIE CO-Attainment | C6: =SUM(C4:C5)/COUNTIF(C4:C5,"<>") -> 83.201923 | D6: =SUM(D4:D5)/COUNTIF(D4:D5,"<>") -> 81.663757 | E6: =SUM(E4:E5)/COUNTIF(E4:E5,"<>") -> 81.734311 | F6: =SUM(F4:F5)/COUNTIF(F4:F5,"<>") -> 87.082626
B11: Direct CO-Attainment | J11: In-Direct CO-Attainment
B12: COs | C12: CO1 | D12: CO2 | E12: CO3 | F12: CO4 | J12: COs | K12: CO1 | L12: CO2 | M12: CO3 | N12: CO4
B13: CIE | C13: =C6 -> 83.201923 | D13: =D6 -> 81.663757 | E13: =E6 -> 81.734311 | F13: =F6 -> 87.082626 | J13: CES | K13: 85 | L13: 85 | M13: 85 | N13: 85
B14: SEE | C14: =K4 -> 36.144578 | D14: =L4 -> 36.144578 | E14: =M4 -> 36.144578 | F14: =N4 -> 36.144578
B15: CIE*60% +SEE*40% | C15: =0.6*C13+0.4*C14 -> 64.378985 | D15: =0.6*D13+0.4*D14 -> 63.456086 | E15: =0.6*E13+0.4*E14 -> 63.498418 | F15: =0.6*F13+0.4*F14 -> 66.707407
E19: Final CO-Attainment
E20: COs | F20: CO1 | G20: CO2 | H20: CO3 | I20: CO4
E21: Direct | F21: =C15 -> 64.378985 | G21: =D15 -> 63.456086 | H21: =E15 -> 63.498418 | I21: =F15 -> 66.707407
E22: IN-Direct | F22: =K13 -> 85 | G22: =L13 -> 85 | H22: =M13 -> 85 | I22: =N13 -> 85
E23: Direct*90% + In-Direcr*10% | F23: =(F21*0.9)+(F22*0.1) -> 66.441087 | G23: =(G21*0.9)+(G22*0.1) -> 65.610477 | H23: =(H21*0.9)+(H22*0.1) -> 65.648576 | I23: =(I21*0.9)+(I22*0.1) -> 68.536666

Sheet PO-Attainment (2)
B3: COs | C3: PO1 | D3: PO2 | E3: PO3 | F3: PO4 | G3: PO5 | H3: PO6 | I3: PO7 | J3: PO8 | K3: PO9 | L3: PO10 | M3: PO11 | N3: PSO1 | O3: PSO2 | P3: PSO3 | R3: FINAL CO-ATTAINMENT | S3: LEVEL | T3: %
B4: CO1 | C4: 3 | R4: CO1 | S4: =T4/100*3 -> 1.9854758 | T4: ='[1]CO-Attainment'!F24 -> 66.182527
B5: CO2 | D5: 3 | F5: 2 | R5: CO2 | S5: =T5/100*3 -> 2.0404187 | T5: ='[1]CO-Attainment'!G24 -> 68.013958
B6: CO3 | E6: 3 | F6: 2 | R6: CO3 | S6: =T6/100*3 -> 1.576287 | T6: ='[1]CO-Attainment'!H24 -> 52.542898
B7: CO4 | F7: 2 | G7: 2 | K7: 1 | L7: 1 | O7: 1 | P7: 1 | R7: CO4 | S7: =T7/100*3 -> 2.1332502 | T7: ='[1]CO-Attainment'!I24 -> 71.108339
C9: =IFERROR(((SUMPRODUCT(C4:C7,$T4:$T7)/100)/COUNTIF(C4:C7,"<>")),"-") -> 1.9854758 | D9: =IFERROR(((SUMPRODUCT(D4:D7,$T4:$T7)/100)/COUNTIF(D4:D7,"<>")),"-") -> 2.0404187 | E9: =IFERROR(((SUMPRODUCT(E4:E7,$T4:$T7)/100)/COUNTIF(E4:E7,"<>")),"-") -> 1.576287 | F9: =IFERROR(((SUMPRODUCT(F4:F7,$T4:$T7)/100)/COUNTIF(F4:F7,"<>")),"-") -> 1.277768 | G9: =IFERROR(((SUMPRODUCT(G4:G7,$T4:$T7)/100)/COUNTIF(G4:G7,"<>")),"-") -> 1.4221668 | H9: =IFERROR(((SUMPRODUCT(H4:H7,$T4:$T7)/100)/COUNTIF(H4:H7,"<>")),"-") -> - | I9: =IFERROR(((SUMPRODUCT(I4:I7,$T4:$T7)/100)/COUNTIF(I4:I7,"<>")),"-") -> - | J9: =IFERROR(((SUMPRODUCT(J4:J7,$T4:$T7)/100)/COUNTIF(J4:J7,"<>")),"-") -> - | ... P9: =IFERROR(((SUMPRODUCT(P4:P7,$T4:$T7)/100)/COUNTIF(P4:P7,"<>")),"-") -> 0.71108339
A10: verification | C10: =IFERROR(SUMPRODUCT((C4:C7<>" ")*($T4:$T7)*(C4:C7))/(3*COUNTIF(C4:C7,"<>")),"-") -> 66.182527 | D10: =IFERROR(SUMPRODUCT((D4:D7<>" ")*($T4:$T7)*(D4:D7))/(3*COUNTIF(D4:D7,"<>")),"-") -> 68.013958 | E10: =IFERROR(SUMPRODUCT((E4:E7<>" ")*($T4:$T7)*(E4:E7))/(3*COUNTIF(E4:E7,"<>")),"-") -> 52.542898 | F10: =IFERROR(SUMPRODUCT((F4:F7<>" ")*($T4:$T7)*(F4:F7))/(3*COUNTIF(F4:F7,"<>")),"-") -> 42.592266 | G10: =IFERROR(SUMPRODUCT((G4:G7<>" ")*($T4:$T7)*(G4:G7))/(3*COUNTIF(G4:G7,"<>")),"-") -> 47.40556 | H10: =IFERROR(SUMPRODUCT((H4:H7<>" ")*($T4:$T7)*(H4:H7))/(3*COUNTIF(H4:H7,"<>")),"-") -> - | I10: =IFERROR(SUMPRODUCT((I4:I7<>" ")*($T4:$T7)*(I4:I7))/(3*COUNTIF(I4:I7,"<>")),"-") -> - | J10: =IFERROR(SUMPRODUCT((J4:J7<>" ")*($T4:$T7)*(J4:J7))/(3*COUNTIF(J4:J7,"<>")),"-") -> - | ... P10: =IFERROR(SUMPRODUCT((P4:P7<>" ")*($T4:$T7)*(P4:P7))/(3*COUNTIF(P4:P7,"<>")),"-") -> 23.70278 | S10: \
A12: verification | C12: =C9*100/3 -> 66.182527 | D12: =D9*100/3 -> 68.013958 | E12: =E9*100/3 -> 52.542898 | F12: =F9*100/3 -> 42.592266 | G12: =G9*100/3 -> 47.40556 | H12: =H9*100/3 -> #VALUE! | I12: =I9*100/3 -> #VALUE! | J12: =J9*100/3 -> #VALUE! | ... P12: =P9*100/3 -> 23.70278
B15: Example of PO-Attainment calculation
B16: PO attainment =(C0 Attainment in %) X ( CO-PO mapping level)
B17: PO1= CO2 attainment in % X CO2-PO2 mapping Level
B18: PO1 = 86.67% X 3 =2.6 or 86.66%
B20: PO4 = (CO3X3+CO4X3)/2
A26: FINAL DIRECT PO-ATTAINMENT
B27: PO1 | C27: PO2 | D27: PO3 | E27: PO4 | F27: PO5 | G27: PO6 | H27: PO7 | I27: PO8 | J27: PO9 | K27: PO10 | L27: PO11 | M27: PSO1 | N27: PSO2 | O27: PSO3
A28: CO1 | B28: =C4*(T4/100) -> 1.9854758
A29: CO2 | C29: =D5*(T5/100) -> 2.0404187 | E29: =F5*(T5/100) -> 1.3602792
A30: CO3 | D30: =E6*(T6/100) -> 1.576287 | E30: =F6*(T6/100) -> 1.050858
A31: CO4 | E31: =F7*(T7/100) -> 1.4221668 | F31: =G7*(T7/100) -> 1.4221668 | J31: =K7*(T7/100) -> 0.71108339 | K31: =L7*(T7/100) -> 0.71108339 | N31: =O7*(T7/100) -> 0.71108339 | O31: =P7*(T7/100) -> 0.71108339
A32: Attainment in Levels | B32: =AVERAGE(B28:B31) -> 1.9854758 | C32: =AVERAGE(C28:C31) -> 2.0404187 | D32: =AVERAGE(D28:D31) -> 1.576287 | E32: =AVERAGE(E28:E31) -> 1.277768 | F32: =AVERAGE(F28:F31) -> 1.4221668 | G32: =AVERAGE(G28:G31) -> #DIV/0! | H32: =AVERAGE(H28:H31) -> #DIV/0! | I32: =AVERAGE(I28:I31) -> #DIV/0! | ... O32: =AVERAGE(O28:O31) -> 0.71108339
A33: Attainment in % | B33: =IFERROR(B32*100/3,"-") -> 66.182527 | C33: =IFERROR(C32*100/3,"-") -> 68.013958 | D33: =IFERROR(D32*100/3,"-") -> 52.542898 | E33: =IFERROR(E32*100/3,"-") -> 42.592266 | F33: =IFERROR(F32*100/3,"-") -> 47.40556 | G33: =IFERROR(G32*100/3,"-") -> - | H33: =IFERROR(H32*100/3,"-") -> - | I33: =IFERROR(I32*100/3,"-") -> - | ... O33: =IFERROR(O32*100/3,"-") -> 23.70278
